SystemError: ../Objects/longobject.c:482: bad argument to internal function

The above exception was the direct cause of the following exception:

Traceback (most recent call last):
  File "/home/F3/src/run_f3.py", line 467, in <module>
    main(config_args().parse_args())
  File "/home/F3/src/run_f3.py", line 463, in main
    run_f3(bench, out_dir)
  File "/home/F3/src/run_f3.py", line 277, in run_f3
    res = solve_problem(prob, label, out_dir)
  File "/home/F3/src/run_f3.py", line 268, in solve_problem
    return run_ltl_test(problem, env, label, out_dir)
  File "/home/F3/src/run_f3.py", line 127, in run_ltl_test
    return search_nonterm(env, symbols, init, trans, fairness,
  File "/home/F3/src/run_f3.py", line 184, in search_nonterm
    _, arg0, arg1 = search_funnel_bmc(env, symbols, init, trans,
  File "/home/F3/src/main.py", line 260, in search_funnel_bmc
    is_rf, args = rf_or_funnel_from_trace(env, symbols, trace, abst_path,
  File "/home/F3/src/main.py", line 714, in rf_or_funnel_from_trace
    model = instantiate_funnel_template(nontermarg)
  File "/home/F3/src/main.py", line 786, in instantiate_funnel_template
    model = funnel_t.motzkin_instantiate(extra=learn if get_fun_learn_ef()
  File "/home/F3/src/funnel.py", line 738, in motzkin_instantiate
    res = solver.solve()
  File "/home/F3/src/multisolver.py", line 103, in solve
    res = self._c_solver.timeout_solve(assumptions=assumptions)
  File "/home/F3/src/multisolver.py", line 197, in solver_timeout_solve
    return self.solve(assumptions)
  File "/usr/local/lib/python3.8/dist-packages/PySMT-0.9.1.dev332-py3.8.egg/pysmt/solvers/solver.py", line 351, in solve
    res = self._solve(assumptions=assumptions)
  File "/usr/local/lib/python3.8/dist-packages/PySMT-0.9.1.dev332-py3.8.egg/pysmt/decorators.py", line 64, in clear_pending_pop_wrap
    return f(self, *args, **kwargs)
  File "/usr/local/lib/python3.8/dist-packages/PySMT-0.9.1.dev332-py3.8.egg/pysmt/solvers/msat.py", line 266, in _solve
    res = mathsat.msat_solve(self.msat_env())
  File "/usr/local/lib/python3.8/dist-packages/mathsat.py", line 1437, in msat_solve
    return _mathsat.msat_solve(e)
SystemError: <built-in function msat_solve> returned a result with an error set
real 3602.00
user 0.00
sys 0.00
