SystemError: ../Objects/longobject.c:482: bad argument to internal function

The above exception was the direct cause of the following exception:

Traceback (most recent call last):
  File "/home/F3/src/run_f3.py", line 444, in <module>
    main(config_args().parse_args())
  File "/home/F3/src/run_f3.py", line 440, in main
    run_f3(bench, out_dir)
  File "/home/F3/src/run_f3.py", line 260, in run_f3
    res = solve_problem(prob, label, out_dir)
  File "/home/F3/src/run_f3.py", line 251, in solve_problem
    return run_ltl_test(problem, env, label, out_dir)
  File "/home/F3/src/run_f3.py", line 113, in run_ltl_test
    return search_nonterm(env, symbols, init, trans, fairness,
  File "/home/F3/src/run_f3.py", line 169, in search_nonterm
    _, arg0, arg1 = search_funnel_bmc(env, symbols, init, trans,
  File "/home/F3/src/main.py", line 250, in search_funnel_bmc
    is_rf, args = rf_or_funnel_from_trace(env, symbols, trace, abst_path,
  File "/home/F3/src/main.py", line 675, in rf_or_funnel_from_trace
    model = instantiate_funnel_template(nontermarg)
  File "/home/F3/src/main.py", line 736, in instantiate_funnel_template
    model, learn = funnel_t.ef_instantiate()
  File "/home/F3/src/funnel.py", line 621, in ef_instantiate
    res, learn = efsolve(self.env, self.parameters, symbs,
  File "/home/F3/src/efsolver.py", line 162, in efsolve
    fres = solve_with_timeout(get_timeout(), fsolver)
  File "/home/F3/src/solver.py", line 117, in solve_with_timeout
    return solver.solve(assumptions)
  File "/usr/local/lib/python3.8/dist-packages/PySMT-0.9.1.dev332-py3.8.egg/pysmt/solvers/solver.py", line 351, in solve
    res = self._solve(assumptions=assumptions)
  File "/usr/local/lib/python3.8/dist-packages/PySMT-0.9.1.dev332-py3.8.egg/pysmt/decorators.py", line 64, in clear_pending_pop_wrap
    return f(self, *args, **kwargs)
  File "/usr/local/lib/python3.8/dist-packages/PySMT-0.9.1.dev332-py3.8.egg/pysmt/solvers/msat.py", line 266, in _solve
    res = mathsat.msat_solve(self.msat_env())
  File "/usr/local/lib/python3.8/dist-packages/mathsat.py", line 1437, in msat_solve
    return _mathsat.msat_solve(e)
SystemError: <built-in function msat_solve> returned a result with an error set
real 3602.56
user 3598.40
sys 4.01
